Workbook

Sheet Executive Summary
A1: EDGE.MEM - GTM & Pricing Workbook
A2: Built only from docs/. Green = documented, amber = TBD, red = conflict or open. No number here is invented.
A4: Topic | B4: Summary | C4: Source
A5: Product overview | B5: EDGE.MEM is an offline-first knowledge engine for industrial edge devices: on-device hybrid (dense + BM25) search, policy-driven data residency, edge-to-cloud sync with explicit conflict cards, federation across devices, snapshot handoff, and an optional cloud LLM. An 8-tab console ships with it. | C5: docs/PRD.md - Goals, Features (shipped)
A6: Target customer | B6: Field technicians at industrial sites (plants, rigs, substations), with reliability engineers and site admins in the same organisation. Which role buys is not documented. | C6: docs/PRD.md - Problem, Users
A7: Core value proposition | B7: Answers and notes are available when connectivity is worst, and notes marked restricted never leave the device, by policy rather than by hope. | C7: docs/PRD.md - Problem, Goals 1-3
A8: GTM strategy | B8: NOT DOCUMENTED. docs/ has no channels, motion, funnel or timeline. The GTM Strategy sheet holds the documented value proposition, demo assets and prerequisites; everything else is TBD. | C8: GTM Strategy sheet
A9: Pricing strategy | B9: NOT DECIDED. No price, tier or billing term exists. The landscape records a market pattern (free/open core, paid sync/hosting/enterprise) and three candidate metrics (per device, per synced GB, per fleet). Pricing sheet is a ready structure with TBD cells. | C9: docs/COMPETITIVE-LANDSCAPE.md - s.5, s.8
A10: Key assumptions | B10: USD as currency (assumption). All revenue-model inputs are blank on purpose. | C10: Assumptions & Sources
A11: Product KPIs (documented) | B11: Offline hybrid search p95 under 10 ms; zero restricted points in cloud collections; audit green in CI. These are product metrics, not GTM metrics. | C11: docs/PRD.md - Success metrics
A12: GTM / revenue KPIs | B12: TBD. No doc defines acquisition, conversion, retention or revenue targets. | C12: -
A14: Readiness dashboard (live formulas)
A15: Measure | B15: Value | C15: Meaning
A16: Revenue model status | B16: ='Revenue Model'!$B$4 -> INCOMPLETE | C16: Complete only when every input is filled and tiers are priced.
A17: Model inputs still blank | B17: ='Assumptions & Sources'!$C$17 -> 8 | C17: Out of 8 numeric inputs.
A18: Documented facts in register | B18: =COUNTIF('Assumptions & Sources'!$E$6:$E$49,"Documented") -> 22 | C18: Have a source document and section.
A19: Calculated values | B19: =COUNTIF('Assumptions & Sources'!$E$6:$E$49,"Calculated") -> 3 | C19: Derived by formula.
A20: Assumptions | B20: =COUNTIF('Assumptions & Sources'!$E$6:$E$49,"Assumption") -> 1 | C20: Necessary but not documented; must be confirmed.
A21: TBD items | B21: =COUNTIF('Assumptions & Sources'!$E$6:$E$49,"TBD") -> 15 | C21: Not documented.
A22: TBD cells in GTM Strategy | B22: =COUNTIF('GTM Strategy'!$A$4:$L$40,"TBD") -> 53 | C22: Channels, motion, KPIs, timeline.
A23: Tiers with a monthly price | B23: =COUNT(Pricing!$F$12:$F$14)&" of 3" -> 0 of 3 | C23: Pricing sheet section B.
A24: Open contradictions | B24: =COUNTIF('Open Items'!$B$5:$B$19,"Contradiction") -> 2 | C24: See Open Items.
A25: Open items in total | B25: =COUNTA('Open Items'!$A$5:$A$19) -> 15 | C25: See Open Items.
A26: Year 1 revenue | B26: ='Revenue Model'!$B$42 -> TBD | C26: TBD until inputs are complete.
A27: Month-24 annualised run-rate | B27: ='Revenue Model'!$B$45 -> TBD | C27: TBD until inputs are complete.

Sheet ICP & Segmentation
A1: ICP & Segmentation
A2: Only S1 is supported by docs/. S2-S5 are hypotheses or out-of-docs inputs and are labelled so. Attractiveness is TBD: no doc scores segments.
A4: ID | B4: Customer segment | C4: Customer type | D4: Company / customer characteristics | E4: Pain points | F4: Needs | G4: Use cases | H4: Buying triggers | I4: Decision makers | J4: Attractiveness | K4: Status | L4: Source
A5: S1 | B5: Industrial sites: plants, rigs, substations | C5: Industrial operator (site-level) | D5: Field technicians work at sites where connectivity is often poor; some notes (personnel, contractor, restricted) must stay on the device. | E5: Cloud-only knowledge bases fail exactly when connectivity is worst; sensitive notes cannot leave the device. | F5: Offline hybrid search (single-digit ms p95 target); policy-driven residency; sync with explicit conflict cards; fleet visibility. | G5: Technician searches past incidents, manuals and sensor context offline and writes notes; reliability engineer reviews synced incidents and distils SOPs; site admin sets residency policy. | H5: TBD | I5: TBD | J5: TBD | K5: Documented (segment + pain); rest TBD | L5: docs/PRD.md - Problem, Users, Goals
A6: S2 | B6: Robots, kiosks, vehicles, mobile devices (edge AI) | C6: Edge-device builders / operators | D6: Devices that must search locally generated information without a continuous cloud dependency. | E6: Limited connectivity, critical latency, data that cannot always leave the device. | F6: Local semantic memory; sync when connectivity returns. | G6: TBD | H6: TBD | I6: TBD | J6: TBD | K6: Not in docs/ - requires confirmation | L6: Hackathon Problem Statement 03 (given in chat; not in docs/)
A7: S3 | B7: Regulated / air-gapped sites | C7: Regulated operator | D7: Hypothesis: sites that need a provable 'data never leaves the device' control. | E7: Hypothesis only. | F7: Provable residency; auth and roles (PRD S9 is open); audit trail of what left the device. | G7: TBD | H7: TBD | I7: TBD | J7: TBD | K7: Hypothesis - unvalidated | L7: docs/COMPETITIVE-LANDSCAPE.md - s.7 (row 1), s.8
A8: S4 | B8: Teams migrating off MongoDB Realm / Atlas Device Sync | C8: Mobile/edge app teams | D8: Hypothesis: apps orphaned by the 2025-09-30 Device Sync shutdown. | E8: Sync service ended. | F8: A replacement sync story. | G8: TBD | H8: Device Sync end-of-life (2025-09-30, secondary sources) | I8: TBD | J8: TBD | K8: Hypothesis - weak fit (EDGE.MEM has no mobile SDK) | L8: docs/COMPETITIVE-LANDSCAPE.md - s.7 (row 2)
A9: S5 | B9: Field-service AI buyers who need offline | C9: Service organisations | D9: Hypothesis: buyers of SaaS field-service AI whose products make no offline claim (Aquant page reviewed; others unread). | E9: Hypothesis only. | F9: Offline retrieval. | G9: TBD | H9: TBD | I9: TBD | J9: TBD | K9: Hypothesis - unvalidated | L9: docs/COMPETITIVE-LANDSCAPE.md - s.7 (row 3)
A11: User roles inside a customer (PRD 'Users'); which role is the buyer is not documented
A12: ID | B12: Role | C12: Type | D12: What they do | I12: Buying role | K12: Status | L12: Source
A13: U1 | B13: Field technician | C13: User | D13: Searches and writes notes on a device, often offline. | I13: TBD | K13: Documented (role); buying role TBD | L13: docs/PRD.md - Users
A14: U2 | B14: Reliability engineer | C14: User | D14: Reviews synced incidents, distils them into SOPs. | I14: TBD | K14: Documented (role); buying role TBD | L14: docs/PRD.md - Users
A15: U3 | B15: Site admin | C15: User / policy owner | D15: Sets data-residency policy and manages the fleet. | I15: TBD | K15: Documented (role); buying role TBD | L15: docs/PRD.md - Users

Sheet GTM Strategy
A1: GTM Strategy
A2: docs/ contains no GTM plan. Channels, motion, KPIs and timeline are TBD. What IS documented: the value proposition, existing demo assets and the prerequisites below.
A4: ID | B4: Target segment | C4: Value proposition | D4: Acquisition channel | E4: Sales channel | F4: Distribution channel (today) | G4: Marketing approach | H4: Sales motion | I4: Key activities | J4: KPIs | K4: Phase / timeline | L4: Status
A5: S1 | B5: Industrial sites | C5: Search past incidents, manuals and sensor context with no network; keep restricted notes on the device by policy; sync with explicit conflict cards when connectivity returns (PRD Problem, Goals 1-3). | D5: TBD | E5: TBD | F5: Self-hosted from the repo via start.sh + bun (README, not docs/); no licence declared - TBD | G5: TBD | H5: TBD | I5: TBD | J5: TBD | K5: TBD | L5: Value prop documented; go-to-market TBD
A6: S2 | B6: Robots, kiosks, vehicles, mobile devices | C6: Local semantic memory without a continuous cloud dependency (Hackathon Problem Statement 03 (given in chat; not in docs/)) | D6: TBD | E6: TBD | F6: Self-hosted from the repo via start.sh + bun (README, not docs/); no licence declared - TBD | G6: TBD | H6: TBD | I6: TBD | J6: TBD | K6: TBD | L6: Not in docs/ - requires confirmation
A7: S3 | B7: Regulated / air-gapped sites | C7: Hypothesis: provable data residency (landscape s.7) | D7: TBD | E7: TBD | F7: Self-hosted from the repo via start.sh + bun (README, not docs/); no licence declared - TBD | G7: TBD | H7: TBD | I7: TBD | J7: TBD | K7: TBD | L7: Hypothesis
A8: S4 | B8: Realm / Device Sync migrants | C8: Hypothesis: replacement sync (landscape s.7) | D8: TBD | E8: TBD | F8: Self-hosted from the repo via start.sh + bun (README, not docs/); no licence declared - TBD | G8: TBD | H8: TBD | I8: TBD | J8: TBD | K8: TBD | L8: Hypothesis
A9: S5 | B9: Field-service AI buyers | C9: Hypothesis: offline retrieval wedge (landscape s.7) | D9: TBD | E9: TBD | F9: Self-hosted from the repo via start.sh + bun (README, not docs/); no licence declared - TBD | G9: TBD | H9: TBD | I9: TBD | J9: TBD | K9: TBD | L9: Hypothesis
A11: Customer journey and conversion stages (template stages; definitions and targets are TBD; assets are documented product features)
A12: # | B12: Stage | C12: Existing product asset (documented) | D12: Conversion metric | E12: Target | F12: Owner | L12: Status
A13: 1 | B13: Awareness | C13: none documented | D13: TBD | E13: TBD | F13: TBD | L13: Template stage - confirm
A14: 2 | B14: Evaluation / demo | C14: Overview tab: fleet-learning hero + demo walkthrough (PRD Features) | D14: TBD | E14: TBD | F14: TBD | L14: Template stage - confirm
A15: 3 | B15: Pilot | C15: Bootstrap a device from cloud; snapshot handoff; policy simulate (PRD Features, Goals 5) | D15: TBD | E15: TBD | F15: TBD | L15: Template stage - confirm
A16: 4 | B16: Purchase | C16: none documented (no pricing, licence or contract terms) | D16: TBD | E16: TBD | F16: TBD | L16: Template stage - confirm
A17: 5 | B17: Onboarding | C17: Policy engine with decision trace; Cloud browser (PRD Features) | D17: TBD | E17: TBD | F17: TBD | L17: Template stage - confirm
A18: 6 | B18: Expansion | C18: Federation across devices; fleet overview (PRD Goals 4, Features) | D18: TBD | E18: TBD | F18: TBD | L18: Template stage - confirm
A20: GTM prerequisites and blockers documented in docs/ (must be resolved before selling)
A21: # | B21: Prerequisite | C21: Detail | D21: Status | E21: Source
A22: 1 | B22: Decide a licence | C22: The repo declares none; nothing is commercially usable until it does. | D22: Open | E22: docs/COMPETITIVE-LANDSCAPE.md - s.8 (product 1)
A23: 2 | B23: Confirm Qdrant Edge redistribution terms | C23: The engine is beta and no licence terms were found on the pages reviewed. | D23: Open | E23: docs/COMPETITIVE-LANDSCAPE.md - s.9 (#3)
A24: 3 | B24: Auth and roles (PRD S9) | C24: No role separation for policy or cloud delete; a multi-user deployment is unsafe. | D24: Open | E24: docs/PRD.md - S9
A25: 4 | B25: Verify the residency differentiator | C25: Couchbase channels and ObjectBox / Turso sync filtering may match it; do not make it the headline until checked. | D25: Open | E25: docs/COMPETITIVE-LANDSCAPE.md - s.8 (product 2), s.9 (#1)
A26: 5 | B26: Audit trail of what left the device | C26: Recommended to close the trust gap Actian sells into. | D26: Recommended - not built | E26: docs/COMPETITIVE-LANDSCAPE.md - s.8 (product 3)
A27: 6 | B27: Re-run the e2e audit | C27: The landscape notes the EDGE.MEM row rests on unit tests; the audit was not re-run. | D27: Open | E27: docs/COMPETITIVE-LANDSCAPE.md - s.9 (#10)
A28: 7 | B28: Buyer interviews | C28: 5 to 10 plant IT/OT or security leads to validate demand and willingness to pay. | D28: Open | E28: docs/COMPETITIVE-LANDSCAPE.md - s.7, s.9 (#9)

Sheet Pricing
A1: Pricing
A2: No price, tier, package or billing term exists in docs/. Structure is ready; every decision cell is TBD (yellow).
A4: A. Pricing decisions
A5: Decision | B5: Value | C5: Source / basis | D5: Status | I5: Notes
A6: Pricing metric (billable unit) | C6: docs/COMPETITIVE-LANDSCAPE.md s.8 (candidates only) | D6: TBD | I6: Options: Per device, Per synced GB, Per fleet, Other.
A7: Free tier offered? | C7: not documented | D7: TBD | I7: Market pattern (landscape s.5): free or open core is common.
A8: Delivery model for paid offering | C8: not documented | D8: TBD | I8: Self-hosted (README today) vs hosted. PRD non-goal excludes multi-tenant SaaS.
A10: B. Tiers and packages (names, prices, billing frequency, limits are inputs)
A11: Tier | B11: Tier name | C11: Target customer | D11: Price (USD) | E11: Billing frequency | F11: Monthly-equivalent price (USD) | G11: Usage limits | H11: Discount | I11: Notes
A12: Tier A | F12: =IF(E12="Monthly",IF(ISNUMBER(D12),D12,"TBD"),IF(E12="Annual",IF(ISNUMBER(D12),D12/12,"TBD"),"TBD")) -> TBD | H12: None documented | I12: Template slot. Rename, or leave blank and set the tier share to 0% on Assumptions & Sources.
A13: Tier B | F13: =IF(E13="Monthly",IF(ISNUMBER(D13),D13,"TBD"),IF(E13="Annual",IF(ISNUMBER(D13),D13/12,"TBD"),"TBD")) -> TBD | H13: None documented | I13: Template slot. Rename, or leave blank and set the tier share to 0% on Assumptions & Sources.
A14: Tier C | F14: =IF(E14="Monthly",IF(ISNUMBER(D14),D14,"TBD"),IF(E14="Annual",IF(ISNUMBER(D14),D14/12,"TBD"),"TBD")) -> TBD | H14: None documented | I14: Template slot. Rename, or leave blank and set the tier share to 0% on Assumptions & Sources.
A16: C. Features by tier (all availability is TBD; features are the shipped ones from the PRD)
A17: Feature | B17: PRD source | D17: Tier A | E17: Tier B | F17: Tier C | I17: Notes
A18: Hybrid dense + BM25 search, on-device, offline | B18: docs/PRD.md - Goals 1; Features: Search | D18: TBD | E18: TBD | F18: TBD
A19: Filters and score breakdown; mode compare | B19: docs/PRD.md - Features: Search | D19: TBD | E19: TBD | F19: TBD
A20: Policy-driven residency (local_only / queued / sync_now) | B20: docs/PRD.md - Goals 2; Features: Policy | D20: TBD | E20: TBD | F20: TBD
A21: Edge-to-cloud sync with explicit conflict cards | B21: docs/PRD.md - Goals 3; Features: Sync | D21: TBD | E21: TBD | F21: TBD
A22: Federation across device processes | B22: docs/PRD.md - Goals 4 | D22: TBD | E22: TBD | F22: TBD
A23: Portable snapshot handoff | B23: docs/PRD.md - Goals 5 | D23: TBD | E23: TBD | F23: TBD
A24: Optional cloud LLM: SOP distill, auto-tag | B24: docs/PRD.md - Goals 6 | D24: TBD | E24: TBD | F24: TBD
A25: Fleet Overview and fleet-learning hero | B25: docs/PRD.md - Features: Overview | D25: TBD | E25: TBD | F25: TBD
A26: Live SSE fleet metrics and export | B26: docs/PRD.md - Features: Metrics | D26: TBD | E26: TBD | F26: TBD
A27: Append-only activity log, search, export | B27: docs/PRD.md - Features: Activity | D27: TBD | E27: TBD | F27: TBD
A28: Cloud collections browser (search / delete) | B28: docs/PRD.md - Features: Cloud | D28: TBD | E28: TBD | F28: TBD
A30: D. Add-ons and expansion (candidates inferred from documented features; none is a decided price)
A31: Item | B31: Basis in docs | D31: Price | H31: Status | I31: Notes
A32: Cloud LLM synthesis (SOP distill, auto-tag) as an add-on | B32: docs/PRD.md Goals 6: optional, never required | D32: TBD | H32: Candidate - not decided | I32: Requires the customer's own LLM endpoint today (README); who pays for LLM usage is undecided.
A33: Expansion: more devices / more sites per customer | B33: docs/PRD.md Goals 4 (federation across devices) | D33: TBD | H33: Candidate - not decided | I33: Also feeds Revenue Model input M05 (unit growth).
A34: Discounts (volume, annual prepay, pilots) | B34: not documented | D34: TBD | H34: TBD
A36: E. Market price benchmarks (competitors' prices, not ours; verified 2026-09-29)
A37: Vendor / plan | B37: Model | C37: Included | D37: Price | E37: Unit | H37: Evidence | I37: Source
A38: Turso Free | B38: Tiered usage | C38: 5 GB storage, 500M reads, 10M writes, 3 GB syncs | D38: 0 | E38: USD/month | H38: Primary pricing page | I38: https://turso.tech/pricing
A39: Turso Developer | B39: Tiered usage | C39: 9 GB, 2.5B reads, 25M writes, 10 GB syncs | D39: 4.99 | E39: USD/month | H39: Primary pricing page | I39: https://turso.tech/pricing
A40: Turso Scaler | B40: Tiered usage | C40: 24 GB, 100B reads, 100M writes, 24 GB syncs | D40: 24.92 | E40: USD/month | H40: Primary pricing page | I40: https://turso.tech/pricing
A41: Turso Pro | B41: Tiered usage | C41: 50 GB, 250B reads, 250M writes, 100 GB syncs | D41: 416.58 | E41: USD/month | H41: Primary pricing page | I41: https://turso.tech/pricing
A42: Qdrant Cloud Free | B42: Free cluster | C42: 0.5 vCPU / 1 GB RAM / 4 GB disk | D42: 0 | E42: USD/month | H42: Primary pricing page | I42: https://qdrant.tech/pricing/
A43: ObjectBox Sync | B43: Paid subscription over free core | C43: Not published | D43: TBD | H43: Primary page | I43: https://objectbox.io/sync/
A44: Actian VectorAI DB | B44: Free Community + trial + Enterprise | C44: Commercial price not published | D44: TBD | H44: Press coverage | I44: see docs/competitive-landscape/landscape.csv (C10)
A46: F. Consistency checks (formulas)
...

Sheet Revenue Model
A1: Revenue Model
A2: Computes only when Assumptions & Sources inputs are complete; until then every line shows TBD. Nothing here is a forecast of record.
A4: Model status | B4: ='Assumptions & Sources'!$C$15 -> INCOMPLETE | C4: Method: churn applies to opening customers; new customers start paying in the month acquired; revenue = MRR (annual-billed cash timing not modelled).
A5: Pricing metric / unit | B5: =IF(ISBLANK(Pricing!$B$6),"TBD",Pricing!$B$6) -> TBD
A6: Currency | B6: ='Assumptions & Sources'!$C$6 -> USD
A8: Inputs (linked, green; edit on Assumptions & Sources)
A9: Opening paying customers | B9: =IF(ISBLANK('Assumptions & Sources'!$C$7),"TBD",'Assumptions & Sources'!$C$7) -> TBD
A10: New paying customers per month | B10: =IF(ISBLANK('Assumptions & Sources'!$C$8),"TBD",'Assumptions & Sources'!$C$8) -> TBD
A11: Monthly logo churn | B11: =IF(ISBLANK('Assumptions & Sources'!$C$9),"TBD",'Assumptions & Sources'!$C$9) -> TBD
A12: Billable units per customer, month 1 | B12: =IF(ISBLANK('Assumptions & Sources'!$C$10),"TBD",'Assumptions & Sources'!$C$10) -> TBD
A13: Monthly growth in units per retained customer | B13: =IF(ISBLANK('Assumptions & Sources'!$C$11),"TBD",'Assumptions & Sources'!$C$11) -> TBD
A14: Tier A share | B14: =IF(ISBLANK('Assumptions & Sources'!$C$12),"TBD",'Assumptions & Sources'!$C$12) -> TBD
A15: Tier B share | B15: =IF(ISBLANK('Assumptions & Sources'!$C$13),"TBD",'Assumptions & Sources'!$C$13) -> TBD
A16: Tier C share | B16: =IF(ISBLANK('Assumptions & Sources'!$C$14),"TBD",'Assumptions & Sources'!$C$14) -> TBD
A17: Tier A monthly-equivalent price | B17: =Pricing!$F$12 -> TBD
A18: Tier B monthly-equivalent price | B18: =Pricing!$F$13 -> TBD
A19: Tier C monthly-equivalent price | B19: =Pricing!$F$14 -> TBD
A21: Monthly projection (24 months)
A22: Line item | B22: Unit | C22: M1 | D22: M2 | E22: M3 | F22: M4 | G22: M5 | H22: M6 | I22: M7 | J22: M8 | K22: M9 | L22: M10 | M22: M11 | N22: M12 | O22: M13 | P22: M14 | Q22: M15 | R22: M16 | S22: M17 | T22: M18 | U22: M19 | V22: M20 | W22: M21 | X22: M22 | Y22: M23 | Z22: M24
A23: Opening customers | B23: customers | C23: =IF($B$4<>"Complete","TBD",$B$9) -> TBD | D23: =IF($B$4<>"Complete","TBD",C26) -> TBD | E23: =IF($B$4<>"Complete","TBD",D26) -> TBD | F23: =IF($B$4<>"Complete","TBD",E26) -> TBD | G23: =IF($B$4<>"Complete","TBD",F26) -> TBD | H23: =IF($B$4<>"Complete","TBD",G26) -> TBD | I23: =IF($B$4<>"Complete","TBD",H26) -> TBD | J23: =IF($B$4<>"Complete","TBD",I26) -> TBD | K23: =IF($B$4<>"Complete","TBD",J26) -> TBD | ... Z23: =IF($B$4<>"Complete","TBD",Y26) -> TBD
A24: New customers | B24: customers | C24: =IF($B$4<>"Complete","TBD",$B$10) -> TBD | D24: =IF($B$4<>"Complete","TBD",$B$10) -> TBD | E24: =IF($B$4<>"Complete","TBD",$B$10) -> TBD | F24: =IF($B$4<>"Complete","TBD",$B$10) -> TBD | G24: =IF($B$4<>"Complete","TBD",$B$10) -> TBD | H24: =IF($B$4<>"Complete","TBD",$B$10) -> TBD | I24: =IF($B$4<>"Complete","TBD",$B$10) -> TBD | J24: =IF($B$4<>"Complete","TBD",$B$10) -> TBD | ... Z24: =IF($B$4<>"Complete","TBD",$B$10) -> TBD
A25: Churned customers | B25: customers | C25: =IF($B$4<>"Complete","TBD",C23*$B$11) -> TBD | D25: =IF($B$4<>"Complete","TBD",D23*$B$11) -> TBD | E25: =IF($B$4<>"Complete","TBD",E23*$B$11) -> TBD | F25: =IF($B$4<>"Complete","TBD",F23*$B$11) -> TBD | G25: =IF($B$4<>"Complete","TBD",G23*$B$11) -> TBD | H25: =IF($B$4<>"Complete","TBD",H23*$B$11) -> TBD | I25: =IF($B$4<>"Complete","TBD",I23*$B$11) -> TBD | J25: =IF($B$4<>"Complete","TBD",J23*$B$11) -> TBD | ... Z25: =IF($B$4<>"Complete","TBD",Z23*$B$11) -> TBD
A26: Closing customers | B26: customers | C26: =IF($B$4<>"Complete","TBD",C23+C24-C25) -> TBD | D26: =IF($B$4<>"Complete","TBD",D23+D24-D25) -> TBD | E26: =IF($B$4<>"Complete","TBD",E23+E24-E25) -> TBD | F26: =IF($B$4<>"Complete","TBD",F23+F24-F25) -> TBD | G26: =IF($B$4<>"Complete","TBD",G23+G24-G25) -> TBD | H26: =IF($B$4<>"Complete","TBD",H23+H24-H25) -> TBD | I26: =IF($B$4<>"Complete","TBD",I23+I24-I25) -> TBD | J26: =IF($B$4<>"Complete","TBD",J23+J24-J25) -> TBD | ... Z26: =IF($B$4<>"Complete","TBD",Z23+Z24-Z25) -> TBD
A27: Billable units per customer | B27: units | C27: =IF($B$4<>"Complete","TBD",$B$12) -> TBD | D27: =IF($B$4<>"Complete","TBD",C27*(1+$B$13)) -> TBD | E27: =IF($B$4<>"Complete","TBD",D27*(1+$B$13)) -> TBD | F27: =IF($B$4<>"Complete","TBD",E27*(1+$B$13)) -> TBD | G27: =IF($B$4<>"Complete","TBD",F27*(1+$B$13)) -> TBD | H27: =IF($B$4<>"Complete","TBD",G27*(1+$B$13)) -> TBD | I27: =IF($B$4<>"Complete","TBD",H27*(1+$B$13)) -> TBD | J27: =IF($B$4<>"Complete","TBD",I27*(1+$B$13)) -> TBD | K27: =IF($B$4<>"Complete","TBD",J27*(1+$B$13)) -> TBD | ... Z27: =IF($B$4<>"Complete","TBD",Y27*(1+$B$13)) -> TBD
A28: Total billable units | B28: units | C28: =IF($B$4<>"Complete","TBD",C26*C27) -> TBD | D28: =IF($B$4<>"Complete","TBD",D26*D27) -> TBD | E28: =IF($B$4<>"Complete","TBD",E26*E27) -> TBD | F28: =IF($B$4<>"Complete","TBD",F26*F27) -> TBD | G28: =IF($B$4<>"Complete","TBD",G26*G27) -> TBD | H28: =IF($B$4<>"Complete","TBD",H26*H27) -> TBD | I28: =IF($B$4<>"Complete","TBD",I26*I27) -> TBD | J28: =IF($B$4<>"Complete","TBD",J26*J27) -> TBD | ... Z28: =IF($B$4<>"Complete","TBD",Z26*Z27) -> TBD
A29: Tier A units | B29: units | C29: =IF($B$4<>"Complete","TBD",C28*$B$14) -> TBD | D29: =IF($B$4<>"Complete","TBD",D28*$B$14) -> TBD | E29: =IF($B$4<>"Complete","TBD",E28*$B$14) -> TBD | F29: =IF($B$4<>"Complete","TBD",F28*$B$14) -> TBD | G29: =IF($B$4<>"Complete","TBD",G28*$B$14) -> TBD | H29: =IF($B$4<>"Complete","TBD",H28*$B$14) -> TBD | I29: =IF($B$4<>"Complete","TBD",I28*$B$14) -> TBD | J29: =IF($B$4<>"Complete","TBD",J28*$B$14) -> TBD | ... Z29: =IF($B$4<>"Complete","TBD",Z28*$B$14) -> TBD
A30: Tier B units | B30: units | C30: =IF($B$4<>"Complete","TBD",C28*$B$15) -> TBD | D30: =IF($B$4<>"Complete","TBD",D28*$B$15) -> TBD | E30: =IF($B$4<>"Complete","TBD",E28*$B$15) -> TBD | F30: =IF($B$4<>"Complete","TBD",F28*$B$15) -> TBD | G30: =IF($B$4<>"Complete","TBD",G28*$B$15) -> TBD | H30: =IF($B$4<>"Complete","TBD",H28*$B$15) -> TBD | I30: =IF($B$4<>"Complete","TBD",I28*$B$15) -> TBD | J30: =IF($B$4<>"Complete","TBD",J28*$B$15) -> TBD | ... Z30: =IF($B$4<>"Complete","TBD",Z28*$B$15) -> TBD
A31: Tier C units | B31: units | C31: =IF($B$4<>"Complete","TBD",C28*$B$16) -> TBD | D31: =IF($B$4<>"Complete","TBD",D28*$B$16) -> TBD | E31: =IF($B$4<>"Complete","TBD",E28*$B$16) -> TBD | F31: =IF($B$4<>"Complete","TBD",F28*$B$16) -> TBD | G31: =IF($B$4<>"Complete","TBD",G28*$B$16) -> TBD | H31: =IF($B$4<>"Complete","TBD",H28*$B$16) -> TBD | I31: =IF($B$4<>"Complete","TBD",I28*$B$16) -> TBD | J31: =IF($B$4<>"Complete","TBD",J28*$B$16) -> TBD | ... Z31: =IF($B$4<>"Complete","TBD",Z28*$B$16) -> TBD
A32: Tier A MRR | B32: currency/month | C32: =IF($B$4<>"Complete","TBD",IF($B$14=0,0,C29*$B$17)) -> TBD | D32: =IF($B$4<>"Complete","TBD",IF($B$14=0,0,D29*$B$17)) -> TBD | E32: =IF($B$4<>"Complete","TBD",IF($B$14=0,0,E29*$B$17)) -> TBD | F32: =IF($B$4<>"Complete","TBD",IF($B$14=0,0,F29*$B$17)) -> TBD | G32: =IF($B$4<>"Complete","TBD",IF($B$14=0,0,G29*$B$17)) -> TBD | H32: =IF($B$4<>"Complete","TBD",IF($B$14=0,0,H29*$B$17)) -> TBD | I32: =IF($B$4<>"Complete","TBD",IF($B$14=0,0,I29*$B$17)) -> TBD | J32: =IF($B$4<>"Complete","TBD",IF($B$14=0,0,J29*$B$17)) -> TBD | ... Z32: =IF($B$4<>"Complete","TBD",IF($B$14=0,0,Z29*$B$17)) -> TBD
A33: Tier B MRR | B33: currency/month | C33: =IF($B$4<>"Complete","TBD",IF($B$15=0,0,C30*$B$18)) -> TBD | D33: =IF($B$4<>"Complete","TBD",IF($B$15=0,0,D30*$B$18)) -> TBD | E33: =IF($B$4<>"Complete","TBD",IF($B$15=0,0,E30*$B$18)) -> TBD | F33: =IF($B$4<>"Complete","TBD",IF($B$15=0,0,F30*$B$18)) -> TBD | G33: =IF($B$4<>"Complete","TBD",IF($B$15=0,0,G30*$B$18)) -> TBD | H33: =IF($B$4<>"Complete","TBD",IF($B$15=0,0,H30*$B$18)) -> TBD | I33: =IF($B$4<>"Complete","TBD",IF($B$15=0,0,I30*$B$18)) -> TBD | J33: =IF($B$4<>"Complete","TBD",IF($B$15=0,0,J30*$B$18)) -> TBD | ... Z33: =IF($B$4<>"Complete","TBD",IF($B$15=0,0,Z30*$B$18)) -> TBD
A34: Tier C MRR | B34: currency/month | C34: =IF($B$4<>"Complete","TBD",IF($B$16=0,0,C31*$B$19)) -> TBD | D34: =IF($B$4<>"Complete","TBD",IF($B$16=0,0,D31*$B$19)) -> TBD | E34: =IF($B$4<>"Complete","TBD",IF($B$16=0,0,E31*$B$19)) -> TBD | F34: =IF($B$4<>"Complete","TBD",IF($B$16=0,0,F31*$B$19)) -> TBD | G34: =IF($B$4<>"Complete","TBD",IF($B$16=0,0,G31*$B$19)) -> TBD | H34: =IF($B$4<>"Complete","TBD",IF($B$16=0,0,H31*$B$19)) -> TBD | I34: =IF($B$4<>"Complete","TBD",IF($B$16=0,0,I31*$B$19)) -> TBD | J34: =IF($B$4<>"Complete","TBD",IF($B$16=0,0,J31*$B$19)) -> TBD | ... Z34: =IF($B$4<>"Complete","TBD",IF($B$16=0,0,Z31*$B$19)) -> TBD
A35: Total MRR | B35: currency/month | C35: =IF($B$4<>"Complete","TBD",C32+C33+C34) -> TBD | D35: =IF($B$4<>"Complete","TBD",D32+D33+D34) -> TBD | E35: =IF($B$4<>"Complete","TBD",E32+E33+E34) -> TBD | F35: =IF($B$4<>"Complete","TBD",F32+F33+F34) -> TBD | G35: =IF($B$4<>"Complete","TBD",G32+G33+G34) -> TBD | H35: =IF($B$4<>"Complete","TBD",H32+H33+H34) -> TBD | I35: =IF($B$4<>"Complete","TBD",I32+I33+I34) -> TBD | J35: =IF($B$4<>"Complete","TBD",J32+J33+J34) -> TBD | ... Z35: =IF($B$4<>"Complete","TBD",Z32+Z33+Z34) -> TBD
A36: Annualised run-rate (MRR x 12) | B36: currency/year | C36: =IF($B$4<>"Complete","TBD",C35*12) -> TBD | D36: =IF($B$4<>"Complete","TBD",D35*12) -> TBD | E36: =IF($B$4<>"Complete","TBD",E35*12) -> TBD | F36: =IF($B$4<>"Complete","TBD",F35*12) -> TBD | G36: =IF($B$4<>"Complete","TBD",G35*12) -> TBD | H36: =IF($B$4<>"Complete","TBD",H35*12) -> TBD | I36: =IF($B$4<>"Complete","TBD",I35*12) -> TBD | J36: =IF($B$4<>"Complete","TBD",J35*12) -> TBD | ... Z36: =IF($B$4<>"Complete","TBD",Z35*12) -> TBD
A37: ARPU (MRR per closing customer) | B37: currency/month | C37: =IF($B$4<>"Complete","TBD",IF(C26=0,0,C35/C26)) -> TBD | D37: =IF($B$4<>"Complete","TBD",IF(D26=0,0,D35/D26)) -> TBD | E37: =IF($B$4<>"Complete","TBD",IF(E26=0,0,E35/E26)) -> TBD | F37: =IF($B$4<>"Complete","TBD",IF(F26=0,0,F35/F26)) -> TBD | G37: =IF($B$4<>"Complete","TBD",IF(G26=0,0,G35/G26)) -> TBD | H37: =IF($B$4<>"Complete","TBD",IF(H26=0,0,H35/H26)) -> TBD | I37: =IF($B$4<>"Complete","TBD",IF(I26=0,0,I35/I26)) -> TBD | J37: =IF($B$4<>"Complete","TBD",IF(J26=0,0,J35/J26)) -> TBD | ... Z37: =IF($B$4<>"Complete","TBD",IF(Z26=0,0,Z35/Z26)) -> TBD
A38: Cumulative revenue | B38: currency | C38: =IF($B$4<>"Complete","TBD",C35) -> TBD | D38: =IF($B$4<>"Complete","TBD",C38+D35) -> TBD | E38: =IF($B$4<>"Complete","TBD",D38+E35) -> TBD | F38: =IF($B$4<>"Complete","TBD",E38+F35) -> TBD | G38: =IF($B$4<>"Complete","TBD",F38+G35) -> TBD | H38: =IF($B$4<>"Complete","TBD",G38+H35) -> TBD | I38: =IF($B$4<>"Complete","TBD",H38+I35) -> TBD | J38: =IF($B$4<>"Complete","TBD",I38+J35) -> TBD | K38: =IF($B$4<>"Complete","TBD",J38+K35) -> TBD | ... Z38: =IF($B$4<>"Complete","TBD",Y38+Z35) -> TBD
A40: Summary (outputs)
A41: Metric | B41: Value
A42: Year 1 revenue (M1-M12) | B42: =IF($B$4<>"Complete","TBD",SUM(C35:N35)) -> TBD
A43: Year 2 revenue (M13-M24) | B43: =IF($B$4<>"Complete","TBD",SUM(O35:Z35)) -> TBD
A44: Month-12 annualised run-rate | B44: =IF($B$4<>"Complete","TBD",N36) -> TBD
...

Sheet Competitive Positioning
A1: Competitive Positioning
A2: Source: docs/competitive-landscape/landscape.csv (researched 2026-09-29). Capability cells: Y stated, N stated absent, ? not stated in sources reviewed (not the same as no).
A4: ID | B4: Competitor | C4: Relationship | D4: Target customer | E4: Pricing (model; detail) | F4: Maturity / limits | G4: On-device vector | H4: Hybrid search | I4: Sync to server | J4: Selective sync | K4: Conflict handling | L4: Ops console | M4: Where they are stronger (vs EDGE.MEM) | N4: Our differentiation | O4: Evidence | P4: Confidence | Q4: Last verified | R4: Source URLs
A5: C01 | B5: Qdrant Edge | C5: Platform / substitute-in-waiting | D5: Robots, kiosks, industrial PCs, drones, mobile, wearables | E5: Not stated | F5: Beta (docs: 'API may change'; edge page: 'Apply to Join the Beta'); ? (not stated on pages reviewed) | G5: Y | H5: Y | I5: Y | J5: ? | K5: ? | L5: ? | M5: EDGE.MEM is built on this engine; Qdrant can ship any of these layers itself (platform risk) | N5: EDGE.MEM adds what the engine does not advertise: policy-driven residency floor, conflict cards, fleet console, LLM workflows | O5: primary-page | P5: High | Q5: 2026-09-29 | R5: https://qdrant.tech/documentation/edge/ https://qdrant.tech/edge/ https://qdrant.tech/blog/qdrant-edge/
A6: C02 | B6: Couchbase Lite + Sync Gateway / Capella App Services | C6: Direct (assembled stack) | D6: Mobile, IoT and edge apps needing offline-first sync | E6: Capella: consumption (per node-hour); Lite EE: per licensed device (agreement language); Per-hour figures seen only on third-party aggregators; not verified | F6: Vector search documented; GA/beta not stated on page reviewed; Vector search marked Enterprise | G6: Y | H6: Y | I6: Y | J6: ? | K6: ? | L6: ? | M6: Mature sync protocol, enterprise vendor, support, multi-platform SDKs; EDGE.MEM is Python-engine + web console only | N6: Open engine choice; residency policy is a first-class, auditable rule set (to confirm vs Couchbase channels) | O6: primary-page (docs) + search-summary (sync, pricing) | P6: Medium | Q6: 2026-09-29 | R6: https://docs.couchbase.com/couchbase-lite/current/android/vector-search.html https://www.couchbase.com/blog/vector-search-at-the-edge-with-couchbase-mobile/ https://www.couchbase.com/products/sync-gateway/ https://www.couchbase.com/pricing/
A7: C03 | B7: ObjectBox (vector DB + Sync) | C7: Direct (assembled stack) | D7: Mobile, IoT, embedded devices | E7: Free core; Sync = paid subscription; Not published (contact sales) | F7: Vector search released early 2024 (vendor claim); Core Apache-2.0; Sync commercial | G7: Y | H7: ? | I7: Y | J7: ? | K7: Y | L7: ? | M7: Native mobile/embedded SDKs (Java, Swift, Dart, C++, Go); small-footprint C++ core; proven sync product | N7: Hybrid dense+BM25 on device (verified in code); residency policy | O7: primary-page | P7: High (features) / n.a. (pricing unpublished) | Q7: 2026-09-29 | R7: https://objectbox.io/vector-database/ https://objectbox.io/sync/
A8: C04 | B8: Turso (libSQL embedded replicas + vector) | C8: Direct (assembled stack) | D8: App developers; per-tenant / per-agent databases | E8: Tiered usage: Free / Developer / Scaler / Pro / Enterprise; Free $0; Developer $4.99/mo; Scaler $24.92/mo; Pro $416.58/mo; Enterprise custom (Turso pricing page) | F8: Embedded replicas GA; offline writes beta; ? | G8: Y | H8: ? | I8: Y | J8: ? | K8: Y | L8: ? | M8: Far cheaper entry point and general SQL; writes offline still beta so gap may close | N8: Purpose-built for knowledge retrieval (hybrid, filters, score breakdown) and residency policy | O8: primary-page | P8: High | Q8: 2026-09-29 | R8: https://turso.tech/pricing https://turso.tech/local-first
A9: C05 | B9: MongoDB Atlas Device Sync / Realm | C9: Displaced incumbent (retired) | D9: Mobile / edge apps that used Realm Sync | E9: n.a. | F9: Discontinued; Realm remains open-source without sync; Realm OSS | G9: n.a. | H9: n.a. | I9: Ended: | J9: n.a. | K9: n.a. | L9: n.a. | M9: EDGE.MEM is not a drop-in Realm replacement (no mobile SDKs) | N9: Teams orphaned by the shutdown need a new sync story (segment opportunity, unquantified) | O9: secondary (search summary of MongoDB forum posts; primary pages returned 403/404) | P9: Medium | Q9: 2026-09-29 | R9: https://www.mongodb.com/community/forums/t/atlas-device-sync-end-of-life-and-deprecation/296687 https://objectbox.io/alternative-to-mongodb-sync/
A10: C06 | B10: LanceDB | C10: Substitute (DIY) | D10: AI/ML developers; multimodal datasets | E10: OSS free; Cloud usage-based; Enterprise custom; Not verified on primary page (pricing URL returned a contact page) | F10: OSS + Cloud (public beta per one source) + Enterprise; Apache-2.0 (OSS) | G10: Y | H10: Y | I10: N | J10: N | K10: N | L10: ? | M10: Strong multimodal/columnar story; larger dev community | N10: Built-in edge-to-server sync, conflicts and residency policy | O10: vendor-comparison (Actian, a competitor) + search-summary | P10: Low-Medium | Q10: 2026-09-29 | R10: https://www.actian.com/blog/developer/comparing-embedded-vector-databases/ https://github.com/lancedb/lancedb https://www.lancedb.com/
A11: C07 | B11: Chroma | C11: Substitute (DIY) | D11: Prototype / RAG developers | E11: ? | F11: ?; OSS (open-source per Actian) | G11: Y | H11: N | I11: N | J11: N | K11: N | L11: ? | M11: Ubiquity and zero-setup for prototypes | N11: Hybrid, sync, policy, conflicts | O11: vendor-comparison (Actian) | P11: Low | Q11: 2026-09-29 | R11: https://www.actian.com/blog/developer/comparing-embedded-vector-databases/
A12: C08 | B12: Milvus Lite | C12: Substitute (DIY) | D12: Python developers prototyping for Milvus | E12: OSS | F12: Documented for small-scale use; ? (not on page) | G12: Y | H12: Y | I12: Manual | J12: N | K12: N | L12: ? | M12: Same ecosystem as Milvus/Zilliz Cloud; Linux and macOS only | N12: Continuous two-way sync with conflicts vs one-shot migration | O12: primary-page | P12: High | Q12: 2026-09-29 | R12: https://milvus.io/docs/milvus_lite.md
A13: C09 | B13: sqlite-vec | C13: Substitute (DIY) | D13: Developers already on SQLite (incl. Raspberry Pi, WASM) | E13: OSS | F13: Pre-v1 ('expect breaking changes'); Apache-2.0 / MIT | G13: Y | H13: ? | I13: N | J13: N | K13: N | L13: ? | M13: Tiny footprint, portability, zero infrastructure; pairs with Turso/others for sync | N13: Turnkey hybrid search, sync, policy | O13: primary-page | P13: High | Q13: 2026-09-29 | R13: https://github.com/asg017/sqlite-vec
A14: C10 | B14: Actian VectorAI DB | C14: Direct (new entrant) | D14: Regulated, disconnected and edge deployments (manufacturing, government) | E14: Free Community Edition, 30-day trial; Enterprise; Commercial pricing not published | F14: Launched 2026-04-28 (press coverage); Commercial; Community Edition free | G14: Y | H14: ? | I14: ? | J14: ? | K14: ? | L14: ? | M14: Enterprise vendor, compliance claims (SOC 2 Type II, HIPAA, GDPR, ISO 27001 — vendor claims), AES-256; EDGE.MEM has none of these certifications | N14: Two-way sync with conflict resolution, residency policy, console (Actian says it has no sync dependency) | O14: vendor-claim + press coverage | P14: Medium | Q14: 2026-09-29 | R14: https://www.actian.com/blog/product-launches/introducing-actian-vectorai-db-ai-where-your-data-lives/ https://www.actian.com/company/press-releases/actian-launches-vectorai-db-with-22x-faster-vector-search-for-production-ai-anywhere-including-the-edge/
A15: C11 | B15: Aquant | C15: Indirect (solves the same user problem) | D15: Field technicians, service teams, call centers (industrial equipment, medical devices, energy, etc.) | E15: Not published | F15: Production; customer case (Makino) cited; SaaS | G15: n.a. | H15: n.a. | I15: n.a. | J15: n.a. | K15: n.a. | L15: Y | M15: Finished product: conversational troubleshooting, voice, analytics, parts agents, customer references | N15: Works with no connectivity; restricted notes never leave the device | O15: primary-page (outcome numbers are vendor claims) | P15: High (capabilities) | Q15: 2026-09-29 | R15: https://www.aquant.ai/solutions/field-technicians
... A19: C15 | B19: Augmentir | C19: Indirect | D19: Frontline maintenance, quality, safety, assembly | E19: ? | F19: Production; SaaS | G19: n.a. | H19: n.a. | I19: n.a. | J19: n.a. | K19: n.a. | L19: Y | M19: Skills management, workflows, collaboration | N19: Offline semantic memory | O19: secondary (comparison site) | P19: Low | Q19: 2026-09-29 | R19: https://sourceforge.net/software/compare/Augmentir-vs-Dozuki/
A20: E00 | B20: EDGE.MEM (this project) | C20: Self | D20: Industrial field technicians, reliability engineers, site admins (docs/PRD.md) | E20: n.a. | F20: Hackathon-stage: no license file, no auth/RBAC, single-threaded engine, depends on Qdrant Edge beta; NONE declared in repo | G20: Y | H20: Y | I20: Y | J20: Y | K20: Y | L20: Y | M20: See docs/COMPETITIVE-LANDSCAPE.md §5 | O20: repo-verified (unit tests; full e2e audit not re-run in this pass) | P20: High | Q20: 2026-09-29 | R20: docs/PRD.md mini-services/edge-engine/src/engine.py mini-services/edge-engine/tests/
A22: Summary counts (formulas over the table above; EDGE.MEM's own row E00 excluded)
B23: Measure | C23: Count
B24: Competitors tracked | C24: =COUNTA(A5:A20)-COUNTIF(A5:A20,"E00") -> 15
B25: Direct competitors | C25: =COUNTIF(C5:C20,"Direct*") -> 4
B26: Indirect competitors | C26: =COUNTIF(C5:C20,"Indirect*") -> 5
B27: Rows at Low / Low-Medium confidence | C27: =COUNTIF(P5:P20,"Low*") -> 6
B28: Competitors with a stated sync-to-server capability (Y) | C28: =COUNTIFS(I5:I20,"Y",A5:A20,"<>E00") -> 4
B29: Competitors with stated conflict handling (Y) | C29: =COUNTIFS(K5:K20,"Y",A5:A20,"<>E00") -> 2

Sheet Assumptions & Sources
A1: Assumptions & Sources
A2: Inputs in blue-on-yellow are the ONLY cells to edit. Blank = not documented. Type: Documented / Calculated / Assumption / TBD.
A4: A. Model inputs (feed the Revenue Model). Leave blank until decided; the model shows TBD until every input is filled.
A5: ID | B5: Input | C5: Value | D5: Unit | E5: Type | F5: Source document | G5: Source section | H5: Status / confidence | I5: Notes
A6: A01 | B6: Reporting currency | C6: USD | D6: text | E6: Assumption | F6: n/a (not documented) | G6: - | H6: Assumption - confirm | I6: No currency appears in docs/. USD used because every sourced benchmark is USD (Turso, Qdrant Cloud). Change if wrong.
A7: M01 | B7: Opening paying customers | D7: customers | E7: TBD | F7: not documented | G7: - | H7: TBD - requires confirmation | I7: Customer counts are not in any doc. Enter 0 for a launch-from-zero case.
A8: M02 | B8: New paying customers per month | D8: customers/month | E8: TBD | F8: not documented | G8: - | H8: TBD - requires confirmation | I8: No acquisition rate, CAC or funnel data exists in docs/.
A9: M03 | B9: Monthly logo churn | D9: % of opening customers | E9: TBD | F9: not documented | G9: - | H9: TBD - requires confirmation | I9: No retention or churn data in docs/. Enter as a percentage, e.g. 2.0%.
A10: M04 | B10: Billable units per customer, month 1 | D10: units/customer | E10: TBD | F10: not documented | G10: - | H10: TBD - requires confirmation | I10: The unit is whatever the Pricing sheet's pricing metric becomes (device, synced GB, fleet...). Undecided.
A11: M05 | B11: Monthly growth in billable units per retained customer | D11: % per month | E11: TBD | F11: not documented | G11: - | H11: TBD - requires confirmation | I11: Expansion driver. No expansion data in docs/.
A12: M06 | B12: Tier A share of billable units | D12: % (A+B+C = 100%) | E12: TBD | F12: not documented | G12: - | H12: TBD - requires confirmation | I12: Tiers are not defined in docs/; see Pricing sheet.
A13: M07 | B13: Tier B share of billable units | D13: % (A+B+C = 100%) | E13: TBD | F13: not documented | G13: - | H13: TBD - requires confirmation
A14: M08 | B14: Tier C share of billable units | D14: % (A+B+C = 100%) | E14: TBD | F14: not documented | G14: - | H14: TBD - requires confirmation | I14: Enter 0% if only two tiers are used.
A15: C01 | B15: Revenue model inputs complete? | C15: =IF(AND(NOT(ISBLANK(Pricing!$B$6)),COUNT($C$7:$C$11)=5,COUNT($C$12:$C$14)=3,ABS(SUM($C$12:$C$14)-1)<0.0001,SUMPRODUCT(($C$12:$C$14>0)*(1-ISNUMBER(Pricing!$F$12:$F$14)))=0),"Complete","INCOMPLETE") -> INCOMPLETE | D15: flag | E15: Calculated | F15: this sheet + Pricing | G15: - | H15: Calculated | I15: Complete only when the pricing metric is chosen, M01-M05 are numbers, tier shares sum to 100%, and every tier with a share > 0 has a price on the Pricing sheet.
A16: C02 | B16: Tier shares total | C16: =SUM($C$12:$C$14) -> 0 | D16: % | E16: Calculated | F16: this sheet | G16: - | H16: Calculated | I16: Must equal 100% before the model computes.
A17: C03 | B17: Model inputs still blank | C17: =COUNTBLANK($C$7:$C$14) -> 8 | D17: count | E17: Calculated | F17: this sheet | G17: - | H17: Calculated
A19: B. Register: documented facts, benchmarks and values the docs leave open
A20: ID | B20: Item | C20: Value | D20: Unit | E20: Type | F20: Source document | G20: Source section | H20: Status / confidence | I20: Notes
A21: D01 | B21: Product name | C21: EDGE.MEM | D21: text | E21: Documented | F21: docs/PRD.md | G21: Title | H21: Documented
A22: D02 | B22: Problem solved | C22: Field technicians at industrial sites need past incidents, manuals and sensor context while offline; some notes must never leave the device. | D22: text | E22: Documented | F22: docs/PRD.md | G22: Problem | H22: Documented | I22: Cloud-only knowledge bases 'fail exactly when connectivity is worst'.
A23: D03 | B23: User roles | C23: Field technician; Reliability engineer; Site admin | D23: text | E23: Documented | F23: docs/PRD.md | G23: Users | H23: Documented | I23: Roles are described as users. Which role buys is not documented.
A24: D04 | B24: Non-goal: multi-tenant SaaS, user accounts, per-user RBAC | C24: Non-goal | D24: text | E24: Documented | F24: docs/PRD.md | G24: Non-goals | H24: Documented | I24: Constrains any hosted or per-user pricing. See Open Items OI-C1.
A25: D05 | B25: Non-goal: untrusted networks without EDGE_TOKEN + firewall | C25: Non-goal | D25: text | E25: Documented | F25: docs/PRD.md | G25: Non-goals | H25: Documented
A26: D06 | B26: Shipped console tabs | C26: 8 | D26: tabs | E26: Documented | F26: docs/PRD.md | G26: Features (shipped) | H26: Documented | I26: Overview, Memory, Search, Sync, Metrics, Activity, Cloud, Policy.
A27: D07 | B27: Auth / role separation for policy + cloud delete (S9) | C27: Open | D27: status | E27: Documented | F27: docs/PRD.md | G27: Security requirements S9 | H27: Documented | I27: Blocks any multi-user or multi-site commercial deployment.
A28: D08 | B28: Snapshot provenance spoofing (S10) | C28: Open (accepted) | D28: status | E28: Documented | F28: docs/PRD.md | G28: Security requirements S10 | H28: Documented
A29: D09 | B29: Autonomous sync when link returns (R7) | C29: Opt-in, default off | D29: status | E29: Documented | F29: docs/PRD.md | G29: Resilience R7 | H29: Documented | I29: Marked a product decision.
A30: D10 | B30: Product success metric: offline hybrid search p95 | C30: < 10 | D30: ms | E30: Documented | F30: docs/PRD.md | G30: Success metrics | H30: Documented | I30: Product KPI, not a GTM KPI.
A31: D11 | B31: Product success metric: restricted points in cloud | C31: 0 | D31: points | E31: Documented | F31: docs/PRD.md | G31: Success metrics | H31: Documented | I31: Product KPI.
A32: D12 | B32: Repository licence | C32: None declared | D32: text | E32: Documented | F32: docs/COMPETITIVE-LANDSCAPE.md | G32: 1 (item 5); CSV row E00 | H32: Documented | I32: No LICENSE file. Blocks commercial distribution.
A33: D13 | B33: Vector engine dependency: Qdrant Edge | C33: Beta; no licence terms found | D33: text | E33: Documented | F33: docs/COMPETITIVE-LANDSCAPE.md | G33: 1 (item 5); 9 (#3) | H33: Documented (primary page) | I33: Redistribution rights unverified.
A34: B01 | B34: Benchmark: Turso Free plan | C34: 0 | D34: USD/month | E34: Documented | F34: docs/COMPETITIVE-LANDSCAPE.md | G34: 5 Pricing | H34: Documented (primary page, 2026-09-29) | I34: 5 GB, 500M reads, 10M writes, 3 GB syncs.
A35: B02 | B35: Benchmark: Turso Developer plan | C35: 4.99 | D35: USD/month | E35: Documented | F35: docs/COMPETITIVE-LANDSCAPE.md | G35: 5 Pricing | H35: Documented (primary page) | I35: A search snippet said $5.99; the pricing page says $4.99.
A36: B03 | B36: Benchmark: Turso Scaler plan | C36: 24.92 | D36: USD/month | E36: Documented | F36: docs/COMPETITIVE-LANDSCAPE.md | G36: 5 Pricing | H36: Documented (primary page)
A37: B04 | B37: Benchmark: Turso Pro plan | C37: 416.58 | D37: USD/month | E37: Documented | F37: docs/COMPETITIVE-LANDSCAPE.md | G37: 5 Pricing | H37: Documented (primary page) | I37: Enterprise: custom.
A38: B05 | B38: Benchmark: Qdrant Cloud free tier | C38: 0.5 vCPU / 1 GB RAM / 4 GB disk | D38: spec | E38: Documented | F38: docs/COMPETITIVE-LANDSCAPE.md | G38: 5 Pricing | H38: Documented (primary page) | I38: Standard = usage-based; Premium = minimum spend; no prices listed.
A39: B06 | B39: Benchmark: ObjectBox Sync price | C39: Not published (contact sales) | D39: text | E39: Documented | F39: docs/COMPETITIVE-LANDSCAPE.md | G39: 5 Pricing | H39: Documented (primary page) | I39: Core is Apache-2.0; Sync is a paid subscription.
A40: B07 | B40: Benchmark: Actian VectorAI DB | C40: Free Community Edition + 30-day trial; commercial price not published | D40: text | E40: Documented | F40: docs/COMPETITIVE-LANDSCAPE.md | G40: 5 Pricing | H40: Vendor / press coverage | I40: Medium confidence.
A41: B08 | B41: Market pricing pattern | C41: Free or open core; money charged for sync, hosting or enterprise features | D41: text | E41: Documented | F41: docs/COMPETITIVE-LANDSCAPE.md | G41: 5 Pricing (last paragraph) | H41: Documented (landscape conclusion) | I41: Metrics seen: rows + synced GB, node-hours, per licensed device.
A42: B09 | B42: Candidate pricing metrics (undecided) | C42: Per device; per synced GB; per fleet | D42: text | E42: Documented | F42: docs/COMPETITIVE-LANDSCAPE.md | G42: 8 Pricing | H42: Options only - no decision | I42: The landscape says choosing needs unit economics and buyer input not in the repo.
...

Sheet Open Items
A1: Open Items
A2: Everything the docs do not settle, and every place where documents pull in different directions. Do not fill these with guesses.
A4: # | B4: Type | C4: Item | D4: Detail | E4: Affects | F4: Source | G4: Needed from
A5: OI-C1 | B5: Contradiction | C5: Non-goal 'multi-tenant SaaS, user accounts, per-user RBAC' vs a commercial pricing model | D5: Per-user, per-seat and hosted pricing all need what the PRD excludes. S9 (role separation) is also open while PRD Users defines three roles. | E5: Pricing; Revenue Model | F5: docs/PRD.md - Non-goals, S9, Users | G5: Founder decision
A6: OI-C2 | B6: Contradiction | C6: Priced offering vs no licence | D6: The landscape says the repo has no licence and Qdrant Edge terms are unread; a price cannot be attached to something that cannot be licensed. | E6: Pricing; GTM | F6: docs/COMPETITIVE-LANDSCAPE.md - s.1, s.9 | G6: Founder / legal
A7: OI-C3 | B7: Tension | C7: PRD 'Features (shipped)' vs landscape 'hackathon-stage' maturity | D7: PRD lists features as shipped; the landscape rates maturity low (no auth, no licence, single-threaded engine, beta engine). | E7: GTM (positioning claims) | F7: docs/PRD.md; docs/COMPETITIVE-LANDSCAPE.md | G7: Founder
A8: OI-C4 | B8: Data quality | C8: Competitive landscape was written in the same session, not by the team | D8: docs/COMPETITIVE-LANDSCAPE.md and its CSV are first-pass research; 6 of 15 rows are Low / Low-Medium confidence. | E8: Competitive Positioning | F8: docs/COMPETITIVE-LANDSCAPE.md | G8: Re-verify at source
A9: OI-M1 | B9: Missing | C9: Pricing metric, tiers, prices, billing terms, discounts | D9: Nothing in docs/ decides them; only candidate metrics (per device / synced GB / fleet). | E9: Pricing; Revenue Model | F9: docs/COMPETITIVE-LANDSCAPE.md - s.8 | G9: Founder + buyer input
A10: OI-M2 | B10: Missing | C10: Customer counts, acquisition rate, churn, expansion | D10: No customer numbers or funnel data exist. | E10: Revenue Model | F10: - | G10: Founder / pilots
A11: OI-M3 | B11: Missing | C11: Acquisition, sales and distribution channels; sales motion | D11: No GTM plan in docs/. | E11: GTM Strategy | F11: - | G11: Founder
A12: OI-M4 | B12: Missing | C12: Buyer persona and decision maker | D12: PRD names users, not buyers. | E12: ICP; GTM | F12: docs/PRD.md - Users | G12: Buyer interviews
A13: OI-M5 | B13: Missing | C13: Market size (TAM/SAM/SOM), geography | D13: Not documented. | E13: Executive Summary; GTM | F13: - | G13: Founder / research
A14: OI-M6 | B14: Missing | C14: CAC, sales cycle, conversion rates, gross margin | D14: Not documented; the model does not use them. | E14: Revenue Model | F14: - | G14: Founder
A15: OI-M7 | B15: Missing | C15: Delivery model: self-hosted vs hosted | D15: README shows self-hosted; hosted conflicts with a PRD non-goal. | E15: Pricing; cost to serve | F15: README (not docs/); docs/PRD.md | G15: Founder
... A19: OI-V1 | B19: Verification | C19: Re-run the e2e audit | D19: Engine and UI changes on 2026-09-29 were checked by unit tests only. | E19: Executive Summary (product KPIs) | F19: docs/COMPETITIVE-LANDSCAPE.md - s.9 (#10) | G19: Engineering
